Workbook
Name TimeList: Lists!$A$2:$A$27
Name DayList: Lists!$G$2:$G$8
Name AppliesList: Lists!$I$2:$I$11

Sheet 說明 Instructions
A1: 使用說明 Instructions
A3: 這個檔案是甚麼？ | B3: 一個自動化的員工排更表。你只需在『員工更表輸入』填時間，其餘頁面會自動更新。
A5: ① 如何輸入員工更期
A6: 步驟 | B6: 到『員工更表輸入』頁，每位員工每天一列。
B7: 用下拉選單選『上班』『下班』時間；有飯鐘就選『飯鐘開始/結束』，沒有就留空。
B8: 放假的日子整列留空即可。『每日時數』與『主排更表』會自動計算。
A10: ② 如何修改員工名單
A11: 步驟 | B11: 到『設定 Settings』頁 ①，直接改 A 欄的員工名稱。
B12: 全檔 (輸入頁、主表、Summary) 會自動跟著新名稱更新，即時生效。
A14: ③ 如何改營業時間 / 時間間隔
A15: 步驟 | B15: 到『設定 Settings』頁 ②，改開始/結束時間或間隔 (15 或 30 分鐘)。
A16: 注意 | B16: 因為這會改變表格的格線數量，改完後需要重新執行 python3 scripts/build_roster.py 才會生效。
B17: 人手規則 (③④) 及員工名稱則是即時生效，不用重跑。
A19: ④ 如何設定人手要求
A20: 步驟 | B20: 『設定 Settings』③ 設預設最低人手；④ 加特別規則 (例：午市 12:00-14:00 需 2 人)。
A21: 適用對象 | B21: 可選『全部 / 平日 / 週末 / 某一天』。多條規則重疊時取最高要求。
A23: ⑤ 長短週與目標時數
A24: 員工類型 | B24: 『設定 Settings』① 每位員工可設『全職 / 兼職』。全職可留空『每週目標時數』。
A25: 長短週 | B25: 『設定 Settings』⑤ 切換『本週類型』長週(48)或短週(40)，兩週平均 44 小時。
A26: 全職目標 | B26: 全職員工本週目標 = 長/短週時數 (除非在『每週目標時數』自填覆寫)。
A27: 兼職目標 | B27: 兼職員工在『每週目標時數』填最低時數即可。
A28: 達標檢視 | B28: Summary ① 的『目標時數 / 差異 / 達標』欄會顯示是否達標 (橙=不足、綠=達標)。
A30: ⑥ 如何看錯誤與顏色提示
A31: 輸入頁 | B31: 『檢查/錯誤提示』欄會用紅底標示：下班早於上班、飯鐘超時、超出營業時間等。
A32: 主排更表 | B32: 紅=無人覆蓋；橙=人手不足；淺綠=正常；灰=飯鐘。每格數字是當值人數。
A34: ⑦ 如何看每週工時 Summary
A35: Summary 頁 | B35: ① 每日/每週時數 + 長短週目標達成；② 每日覆蓋概況；③ 問題時段清單。
A37: 日後可加入的規則 | B37: 固定放假日、兼職每週最低時數細則、飯鐘規則、分段班次、輪替長短週自動排程等 (可再請我擴充)。

Sheet 設定 Settings
A1: 設定 Settings — 你可以在這裡修改參數
A3: ① 員工名單 (可改名 / 即時生效)
A4: 員工 | B4: 代表色 | C4: 類型 | D4: 每週目標時數
A5: 菁 | C5: 全職
A6: Kerry | C6: 全職
A7: Ice | C7: 全職
A8: Brielle | C8: 全職
A9: 琳琳 | C9: 全職
A11: ② 營業 / 排班時間 (改後需重跑 Python 程式)
A12: 每日開始時間 | B12: 0.40625
A13: 每日結束時間 | B13: 0.92708333
A14: 時間間隔 (分鐘) | B14: 30
A16: ③ 人手設定 (即時生效)
A17: 預設每時段最低人手 | B17: 1
A19: ④ 特別時段人手規則 (午市 / 晚市 / 週末等)
A20: 適用對象 | B20: 由 | C20: 至 | D20: 最低人手
A21: 全部 | B21: 0.5 | C21: 0.58333333 | D21: 2
A22: 全部 | B22: 0.75 | C22: 0.875 | D22: 2
A23: 週末 | B23: 0.40625 | C23: 0.92708333 | D23: 2
A28: ⑤ 長短週設定 (全職：短週 40、長週 48，平均 44)
A29: 本週類型 | B29: 長週
A30: 長週目標時數 | B30: 48
A31: 短週目標時數 | B31: 40
A32: 兩週平均 (參考) | B32: =(B30+B31)/2

Sheet 員工更表輸入
A1: 員工更表輸入 — 只需在這裡輸入每天的上班/下班/飯鐘時間
A2: 提示：時間請用下拉選單選擇；放假的日子留空即可。飯鐘可留空。
A4: 員工 | B4: 星期 | C4: 上班 | D4: 下班 | E4: 飯鐘開始 | F4: 飯鐘結束 | G4: 每日時數 | H4: 檢查 / 錯誤提示
A5: ='設定 Settings'!$A$5 | B5: 星期一 | C5: 0.40625 | D5: 0.78125 | E5: 0.54166667 | F5: 0.57291667 | G5: =IF(OR($C$5="",$D$5=""),"",($D$5-$C$5-IF(OR($E$5="",$F$5=""),0,$F$5-$E$5))*24) | H5: =IF(AND($C$5<>"",$D$5<>"",$D$5<=$C$5),"下班需晚於上班",IF(AND($E$5<>"",$F$5<>"",$F$5<=$E$5),"飯鐘結束需晚於開始",IF(AND($E$5<>"",$F$5<>"",OR($E$5<$C$5,$F$5>$D$5)),"飯鐘超出更時",IF(AND($C$5<>"",OR($C$5<'設定 Settings'!$B$12,$D$5>'設定 Settings'!$B$13)),"超出營業時間",""))))
A6: ='設定 Settings'!$A$5 | B6: 星期二 | C6: 0.40625 | D6: 0.78125 | E6: 0.54166667 | F6: 0.57291667 | G6: =IF(OR($C$6="",$D$6=""),"",($D$6-$C$6-IF(OR($E$6="",$F$6=""),0,$F$6-$E$6))*24) | H6: =IF(AND($C$6<>"",$D$6<>"",$D$6<=$C$6),"下班需晚於上班",IF(AND($E$6<>"",$F$6<>"",$F$6<=$E$6),"飯鐘結束需晚於開始",IF(AND($E$6<>"",$F$6<>"",OR($E$6<$C$6,$F$6>$D$6)),"飯鐘超出更時",IF(AND($C$6<>"",OR($C$6<'設定 Settings'!$B$12,$D$6>'設定 Settings'!$B$13)),"超出營業時間",""))))
A7: ='設定 Settings'!$A$5 | B7: 星期三 | C7: 0.40625 | D7: 0.78125 | E7: 0.54166667 | F7: 0.57291667 | G7: =IF(OR($C$7="",$D$7=""),"",($D$7-$C$7-IF(OR($E$7="",$F$7=""),0,$F$7-$E$7))*24) | H7: =IF(AND($C$7<>"",$D$7<>"",$D$7<=$C$7),"下班需晚於上班",IF(AND($E$7<>"",$F$7<>"",$F$7<=$E$7),"飯鐘結束需晚於開始",IF(AND($E$7<>"",$F$7<>"",OR($E$7<$C$7,$F$7>$D$7)),"飯鐘超出更時",IF(AND($C$7<>"",OR($C$7<'設定 Settings'!$B$12,$D$7>'設定 Settings'!$B$13)),"超出營業時間",""))))
A8: ='設定 Settings'!$A$5 | B8: 星期四 | C8: 0.40625 | D8: 0.78125 | E8: 0.54166667 | F8: 0.57291667 | G8: =IF(OR($C$8="",$D$8=""),"",($D$8-$C$8-IF(OR($E$8="",$F$8=""),0,$F$8-$E$8))*24) | H8: =IF(AND($C$8<>"",$D$8<>"",$D$8<=$C$8),"下班需晚於上班",IF(AND($E$8<>"",$F$8<>"",$F$8<=$E$8),"飯鐘結束需晚於開始",IF(AND($E$8<>"",$F$8<>"",OR($E$8<$C$8,$F$8>$D$8)),"飯鐘超出更時",IF(AND($C$8<>"",OR($C$8<'設定 Settings'!$B$12,$D$8>'設定 Settings'!$B$13)),"超出營業時間",""))))
A9: ='設定 Settings'!$A$5 | B9: 星期五 | C9: 0.40625 | D9: 0.78125 | E9: 0.54166667 | F9: 0.57291667 | G9: =IF(OR($C$9="",$D$9=""),"",($D$9-$C$9-IF(OR($E$9="",$F$9=""),0,$F$9-$E$9))*24) | H9: =IF(AND($C$9<>"",$D$9<>"",$D$9<=$C$9),"下班需晚於上班",IF(AND($E$9<>"",$F$9<>"",$F$9<=$E$9),"飯鐘結束需晚於開始",IF(AND($E$9<>"",$F$9<>"",OR($E$9<$C$9,$F$9>$D$9)),"飯鐘超出更時",IF(AND($C$9<>"",OR($C$9<'設定 Settings'!$B$12,$D$9>'設定 Settings'!$B$13)),"超出營業時間",""))))
A10: ='設定 Settings'!$A$5 | B10: 星期六 | C10: 0.40625 | D10: 0.78125 | E10: 0.54166667 | F10: 0.57291667 | G10: =IF(OR($C$10="",$D$10=""),"",($D$10-$C$10-IF(OR($E$10="",$F$10=""),0,$F$10-$E$10))*24) | H10: =IF(AND($C$10<>"",$D$10<>"",$D$10<=$C$10),"下班需晚於上班",IF(AND($E$10<>"",$F$10<>"",$F$10<=$E$10),"飯鐘結束需晚於開始",IF(AND($E$10<>"",$F$10<>"",OR($E$10<$C$10,$F$10>$D$10)),"飯鐘超出更時",IF(AND($C$10<>"",OR($C$10<'設定 Settings'!$B$12,$D$10>'設定 Settings'!$B$13)),"超出營業時間",""))))
A11: ='設定 Settings'!$A$5 | B11: 星期日 | G11: =IF(OR($C$11="",$D$11=""),"",($D$11-$C$11-IF(OR($E$11="",$F$11=""),0,$F$11-$E$11))*24) | H11: =IF(AND($C$11<>"",$D$11<>"",$D$11<=$C$11),"下班需晚於上班",IF(AND($E$11<>"",$F$11<>"",$F$11<=$E$11),"飯鐘結束需晚於開始",IF(AND($E$11<>"",$F$11<>"",OR($E$11<$C$11,$F$11>$D$11)),"飯鐘超出更時",IF(AND($C$11<>"",OR($C$11<'設定 Settings'!$B$12,$D$11>'設定 Settings'!$B$13)),"超出營業時間",""))))
A12: ='設定 Settings'!$A$6 | B12: 星期一 | C12: 0.55208333 | D12: 0.92708333 | E12: 0.72916667 | F12: 0.76041667 | G12: =IF(OR($C$12="",$D$12=""),"",($D$12-$C$12-IF(OR($E$12="",$F$12=""),0,$F$12-$E$12))*24) | H12: =IF(AND($C$12<>"",$D$12<>"",$D$12<=$C$12),"下班需晚於上班",IF(AND($E$12<>"",$F$12<>"",$F$12<=$E$12),"飯鐘結束需晚於開始",IF(AND($E$12<>"",$F$12<>"",OR($E$12<$C$12,$F$12>$D$12)),"飯鐘超出更時",IF(AND($C$12<>"",OR($C$12<'設定 Settings'!$B$12,$D$12>'設定 Settings'!$B$13)),"超出營業時間",""))))
A13: ='設定 Settings'!$A$6 | B13: 星期二 | C13: 0.55208333 | D13: 0.92708333 | E13: 0.72916667 | F13: 0.76041667 | G13: =IF(OR($C$13="",$D$13=""),"",($D$13-$C$13-IF(OR($E$13="",$F$13=""),0,$F$13-$E$13))*24) | H13: =IF(AND($C$13<>"",$D$13<>"",$D$13<=$C$13),"下班需晚於上班",IF(AND($E$13<>"",$F$13<>"",$F$13<=$E$13),"飯鐘結束需晚於開始",IF(AND($E$13<>"",$F$13<>"",OR($E$13<$C$13,$F$13>$D$13)),"飯鐘超出更時",IF(AND($C$13<>"",OR($C$13<'設定 Settings'!$B$12,$D$13>'設定 Settings'!$B$13)),"超出營業時間",""))))
A14: ='設定 Settings'!$A$6 | B14: 星期三 | C14: 0.55208333 | D14: 0.92708333 | E14: 0.72916667 | F14: 0.76041667 | G14: =IF(OR($C$14="",$D$14=""),"",($D$14-$C$14-IF(OR($E$14="",$F$14=""),0,$F$14-$E$14))*24) | H14: =IF(AND($C$14<>"",$D$14<>"",$D$14<=$C$14),"下班需晚於上班",IF(AND($E$14<>"",$F$14<>"",$F$14<=$E$14),"飯鐘結束需晚於開始",IF(AND($E$14<>"",$F$14<>"",OR($E$14<$C$14,$F$14>$D$14)),"飯鐘超出更時",IF(AND($C$14<>"",OR($C$14<'設定 Settings'!$B$12,$D$14>'設定 Settings'!$B$13)),"超出營業時間",""))))
A15: ='設定 Settings'!$A$6 | B15: 星期四 | C15: 0.55208333 | D15: 0.92708333 | E15: 0.72916667 | F15: 0.76041667 | G15: =IF(OR($C$15="",$D$15=""),"",($D$15-$C$15-IF(OR($E$15="",$F$15=""),0,$F$15-$E$15))*24) | H15: =IF(AND($C$15<>"",$D$15<>"",$D$15<=$C$15),"下班需晚於上班",IF(AND($E$15<>"",$F$15<>"",$F$15<=$E$15),"飯鐘結束需晚於開始",IF(AND($E$15<>"",$F$15<>"",OR($E$15<$C$15,$F$15>$D$15)),"飯鐘超出更時",IF(AND($C$15<>"",OR($C$15<'設定 Settings'!$B$12,$D$15>'設定 Settings'!$B$13)),"超出營業時間",""))))
A16: ='設定 Settings'!$A$6 | B16: 星期五 | C16: 0.55208333 | D16: 0.92708333 | E16: 0.72916667 | F16: 0.76041667 | G16: =IF(OR($C$16="",$D$16=""),"",($D$16-$C$16-IF(OR($E$16="",$F$16=""),0,$F$16-$E$16))*24) | H16: =IF(AND($C$16<>"",$D$16<>"",$D$16<=$C$16),"下班需晚於上班",IF(AND($E$16<>"",$F$16<>"",$F$16<=$E$16),"飯鐘結束需晚於開始",IF(AND($E$16<>"",$F$16<>"",OR($E$16<$C$16,$F$16>$D$16)),"飯鐘超出更時",IF(AND($C$16<>"",OR($C$16<'設定 Settings'!$B$12,$D$16>'設定 Settings'!$B$13)),"超出營業時間",""))))
A17: ='設定 Settings'!$A$6 | B17: 星期六 | C17: 0.55208333 | D17: 0.92708333 | E17: 0.72916667 | F17: 0.76041667 | G17: =IF(OR($C$17="",$D$17=""),"",($D$17-$C$17-IF(OR($E$17="",$F$17=""),0,$F$17-$E$17))*24) | H17: =IF(AND($C$17<>"",$D$17<>"",$D$17<=$C$17),"下班需晚於上班",IF(AND($E$17<>"",$F$17<>"",$F$17<=$E$17),"飯鐘結束需晚於開始",IF(AND($E$17<>"",$F$17<>"",OR($E$17<$C$17,$F$17>$D$17)),"飯鐘超出更時",IF(AND($C$17<>"",OR($C$17<'設定 Settings'!$B$12,$D$17>'設定 Settings'!$B$13)),"超出營業時間",""))))
A18: ='設定 Settings'!$A$6 | B18: 星期日 | G18: =IF(OR($C$18="",$D$18=""),"",($D$18-$C$18-IF(OR($E$18="",$F$18=""),0,$F$18-$E$18))*24) | H18: =IF(AND($C$18<>"",$D$18<>"",$D$18<=$C$18),"下班需晚於上班",IF(AND($E$18<>"",$F$18<>"",$F$18<=$E$18),"飯鐘結束需晚於開始",IF(AND($E$18<>"",$F$18<>"",OR($E$18<$C$18,$F$18>$D$18)),"飯鐘超出更時",IF(AND($C$18<>"",OR($C$18<'設定 Settings'!$B$12,$D$18>'設定 Settings'!$B$13)),"超出營業時間",""))))
A19: ='設定 Settings'!$A$7 | B19: 星期一 | G19: =IF(OR($C$19="",$D$19=""),"",($D$19-$C$19-IF(OR($E$19="",$F$19=""),0,$F$19-$E$19))*24) | H19: =IF(AND($C$19<>"",$D$19<>"",$D$19<=$C$19),"下班需晚於上班",IF(AND($E$19<>"",$F$19<>"",$F$19<=$E$19),"飯鐘結束需晚於開始",IF(AND($E$19<>"",$F$19<>"",OR($E$19<$C$19,$F$19>$D$19)),"飯鐘超出更時",IF(AND($C$19<>"",OR($C$19<'設定 Settings'!$B$12,$D$19>'設定 Settings'!$B$13)),"超出營業時間",""))))
A20: ='設定 Settings'!$A$7 | B20: 星期二 | G20: =IF(OR($C$20="",$D$20=""),"",($D$20-$C$20-IF(OR($E$20="",$F$20=""),0,$F$20-$E$20))*24) | H20: =IF(AND($C$20<>"",$D$20<>"",$D$20<=$C$20),"下班需晚於上班",IF(AND($E$20<>"",$F$20<>"",$F$20<=$E$20),"飯鐘結束需晚於開始",IF(AND($E$20<>"",$F$20<>"",OR($E$20<$C$20,$F$20>$D$20)),"飯鐘超出更時",IF(AND($C$20<>"",OR($C$20<'設定 Settings'!$B$12,$D$20>'設定 Settings'!$B$13)),"超出營業時間",""))))
A21: ='設定 Settings'!$A$7 | B21: 星期三 | C21: 0.70833333 | D21: 0.92708333 | G21: =IF(OR($C$21="",$D$21=""),"",($D$21-$C$21-IF(OR($E$21="",$F$21=""),0,$F$21-$E$21))*24) | H21: =IF(AND($C$21<>"",$D$21<>"",$D$21<=$C$21),"下班需晚於上班",IF(AND($E$21<>"",$F$21<>"",$F$21<=$E$21),"飯鐘結束需晚於開始",IF(AND($E$21<>"",$F$21<>"",OR($E$21<$C$21,$F$21>$D$21)),"飯鐘超出更時",IF(AND($C$21<>"",OR($C$21<'設定 Settings'!$B$12,$D$21>'設定 Settings'!$B$13)),"超出營業時間",""))))
A22: ='設定 Settings'!$A$7 | B22: 星期四 | C22: 0.70833333 | D22: 0.92708333 | G22: =IF(OR($C$22="",$D$22=""),"",($D$22-$C$22-IF(OR($E$22="",$F$22=""),0,$F$22-$E$22))*24) | H22: =IF(AND($C$22<>"",$D$22<>"",$D$22<=$C$22),"下班需晚於上班",IF(AND($E$22<>"",$F$22<>"",$F$22<=$E$22),"飯鐘結束需晚於開始",IF(AND($E$22<>"",$F$22<>"",OR($E$22<$C$22,$F$22>$D$22)),"飯鐘超出更時",IF(AND($C$22<>"",OR($C$22<'設定 Settings'!$B$12,$D$22>'設定 Settings'!$B$13)),"超出營業時間",""))))
A23: ='設定 Settings'!$A$7 | B23: 星期五 | C23: 0.70833333 | D23: 0.92708333 | G23: =IF(OR($C$23="",$D$23=""),"",($D$23-$C$23-IF(OR($E$23="",$F$23=""),0,$F$23-$E$23))*24) | H23: =IF(AND($C$23<>"",$D$23<>"",$D$23<=$C$23),"下班需晚於上班",IF(AND($E$23<>"",$F$23<>"",$F$23<=$E$23),"飯鐘結束需晚於開始",IF(AND($E$23<>"",$F$23<>"",OR($E$23<$C$23,$F$23>$D$23)),"飯鐘超出更時",IF(AND($C$23<>"",OR($C$23<'設定 Settings'!$B$12,$D$23>'設定 Settings'!$B$13)),"超出營業時間",""))))
A24: ='設定 Settings'!$A$7 | B24: 星期六 | C24: 0.40625 | D24: 0.75 | E24: 0.54166667 | F24: 0.57291667 | G24: =IF(OR($C$24="",$D$24=""),"",($D$24-$C$24-IF(OR($E$24="",$F$24=""),0,$F$24-$E$24))*24) | H24: =IF(AND($C$24<>"",$D$24<>"",$D$24<=$C$24),"下班需晚於上班",IF(AND($E$24<>"",$F$24<>"",$F$24<=$E$24),"飯鐘結束需晚於開始",IF(AND($E$24<>"",$F$24<>"",OR($E$24<$C$24,$F$24>$D$24)),"飯鐘超出更時",IF(AND($C$24<>"",OR($C$24<'設定 Settings'!$B$12,$D$24>'設定 Settings'!$B$13)),"超出營業時間",""))))
A25: ='設定 Settings'!$A$7 | B25: 星期日 | C25: 0.40625 | D25: 0.75 | E25: 0.54166667 | F25: 0.57291667 | G25: =IF(OR($C$25="",$D$25=""),"",($D$25-$C$25-IF(OR($E$25="",$F$25=""),0,$F$25-$E$25))*24) | H25: =IF(AND($C$25<>"",$D$25<>"",$D$25<=$C$25),"下班需晚於上班",IF(AND($E$25<>"",$F$25<>"",$F$25<=$E$25),"飯鐘結束需晚於開始",IF(AND($E$25<>"",$F$25<>"",OR($E$25<$C$25,$F$25>$D$25)),"飯鐘超出更時",IF(AND($C$25<>"",OR($C$25<'設定 Settings'!$B$12,$D$25>'設定 Settings'!$B$13)),"超出營業時間",""))))
A26: ='設定 Settings'!$A$8 | B26: 星期一 | C26: 0.66666667 | D26: 0.92708333 | G26: =IF(OR($C$26="",$D$26=""),"",($D$26-$C$26-IF(OR($E$26="",$F$26=""),0,$F$26-$E$26))*24) | H26: =IF(AND($C$26<>"",$D$26<>"",$D$26<=$C$26),"下班需晚於上班",IF(AND($E$26<>"",$F$26<>"",$F$26<=$E$26),"飯鐘結束需晚於開始",IF(AND($E$26<>"",$F$26<>"",OR($E$26<$C$26,$F$26>$D$26)),"飯鐘超出更時",IF(AND($C$26<>"",OR($C$26<'設定 Settings'!$B$12,$D$26>'設定 Settings'!$B$13)),"超出營業時間",""))))
A27: ='設定 Settings'!$A$8 | B27: 星期二 | C27: 0.66666667 | D27: 0.92708333 | G27: =IF(OR($C$27="",$D$27=""),"",($D$27-$C$27-IF(OR($E$27="",$F$27=""),0,$F$27-$E$27))*24) | H27: =IF(AND($C$27<>"",$D$27<>"",$D$27<=$C$27),"下班需晚於上班",IF(AND($E$27<>"",$F$27<>"",$F$27<=$E$27),"飯鐘結束需晚於開始",IF(AND($E$27<>"",$F$27<>"",OR($E$27<$C$27,$F$27>$D$27)),"飯鐘超出更時",IF(AND($C$27<>"",OR($C$27<'設定 Settings'!$B$12,$D$27>'設定 Settings'!$B$13)),"超出營業時間",""))))
A28: ='設定 Settings'!$A$8 | B28: 星期三 | G28: =IF(OR($C$28="",$D$28=""),"",($D$28-$C$28-IF(OR($E$28="",$F$28=""),0,$F$28-$E$28))*24) | H28: =IF(AND($C$28<>"",$D$28<>"",$D$28<=$C$28),"下班需晚於上班",IF(AND($E$28<>"",$F$28<>"",$F$28<=$E$28),"飯鐘結束需晚於開始",IF(AND($E$28<>"",$F$28<>"",OR($E$28<$C$28,$F$28>$D$28)),"飯鐘超出更時",IF(AND($C$28<>"",OR($C$28<'設定 Settings'!$B$12,$D$28>'設定 Settings'!$B$13)),"超出營業時間",""))))
A29: ='設定 Settings'!$A$8 | B29: 星期四 | G29: =IF(OR($C$29="",$D$29=""),"",($D$29-$C$29-IF(OR($E$29="",$F$29=""),0,$F$29-$E$29))*24) | H29: =IF(AND($C$29<>"",$D$29<>"",$D$29<=$C$29),"下班需晚於上班",IF(AND($E$29<>"",$F$29<>"",$F$29<=$E$29),"飯鐘結束需晚於開始",IF(AND($E$29<>"",$F$29<>"",OR($E$29<$C$29,$F$29>$D$29)),"飯鐘超出更時",IF(AND($C$29<>"",OR($C$29<'設定 Settings'!$B$12,$D$29>'設定 Settings'!$B$13)),"超出營業時間",""))))
A30: ='設定 Settings'!$A$8 | B30: 星期五 | G30: =IF(OR($C$30="",$D$30=""),"",($D$30-$C$30-IF(OR($E$30="",$F$30=""),0,$F$30-$E$30))*24) | H30: =IF(AND($C$30<>"",$D$30<>"",$D$30<=$C$30),"下班需晚於上班",IF(AND($E$30<>"",$F$30<>"",$F$30<=$E$30),"飯鐘結束需晚於開始",IF(AND($E$30<>"",$F$30<>"",OR($E$30<$C$30,$F$30>$D$30)),"飯鐘超出更時",IF(AND($C$30<>"",OR($C$30<'設定 Settings'!$B$12,$D$30>'設定 Settings'!$B$13)),"超出營業時間",""))))
A31: ='設定 Settings'!$A$8 | B31: 星期六 | G31: =IF(OR($C$31="",$D$31=""),"",($D$31-$C$31-IF(OR($E$31="",$F$31=""),0,$F$31-$E$31))*24) | H31: =IF(AND($C$31<>"",$D$31<>"",$D$31<=$C$31),"下班需晚於上班",IF(AND($E$31<>"",$F$31<>"",$F$31<=$E$31),"飯鐘結束需晚於開始",IF(AND($E$31<>"",$F$31<>"",OR($E$31<$C$31,$F$31>$D$31)),"飯鐘超出更時",IF(AND($C$31<>"",OR($C$31<'設定 Settings'!$B$12,$D$31>'設定 Settings'!$B$13)),"超出營業時間",""))))
A32: ='設定 Settings'!$A$8 | B32: 星期日 | C32: 0.40625 | D32: 0.92708333 | E32: 0.58333333 | F32: 0.625 | G32: =IF(OR($C$32="",$D$32=""),"",($D$32-$C$32-IF(OR($E$32="",$F$32=""),0,$F$32-$E$32))*24) | H32: =IF(AND($C$32<>"",$D$32<>"",$D$32<=$C$32),"下班需晚於上班",IF(AND($E$32<>"",$F$32<>"",$F$32<=$E$32),"飯鐘結束需晚於開始",IF(AND($E$32<>"",$F$32<>"",OR($E$32<$C$32,$F$32>$D$32)),"飯鐘超出更時",IF(AND($C$32<>"",OR($C$32<'設定 Settings'!$B$12,$D$32>'設定 Settings'!$B$13)),"超出營業時間",""))))
A33: ='設定 Settings'!$A$9 | B33: 星期一 | G33: =IF(OR($C$33="",$D$33=""),"",($D$33-$C$33-IF(OR($E$33="",$F$33=""),0,$F$33-$E$33))*24) | H33: =IF(AND($C$33<>"",$D$33<>"",$D$33<=$C$33),"下班需晚於上班",IF(AND($E$33<>"",$F$33<>"",$F$33<=$E$33),"飯鐘結束需晚於開始",IF(AND($E$33<>"",$F$33<>"",OR($E$33<$C$33,$F$33>$D$33)),"飯鐘超出更時",IF(AND($C$33<>"",OR($C$33<'設定 Settings'!$B$12,$D$33>'設定 Settings'!$B$13)),"超出營業時間",""))))
A34: ='設定 Settings'!$A$9 | B34: 星期二 | G34: =IF(OR($C$34="",$D$34=""),"",($D$34-$C$34-IF(OR($E$34="",$F$34=""),0,$F$34-$E$34))*24) | H34: =IF(AND($C$34<>"",$D$34<>"",$D$34<=$C$34),"下班需晚於上班",IF(AND($E$34<>"",$F$34<>"",$F$34<=$E$34),"飯鐘結束需晚於開始",IF(AND($E$34<>"",$F$34<>"",OR($E$34<$C$34,$F$34>$D$34)),"飯鐘超出更時",IF(AND($C$34<>"",OR($C$34<'設定 Settings'!$B$12,$D$34>'設定 Settings'!$B$13)),"超出營業時間",""))))
A35: ='設定 Settings'!$A$9 | B35: 星期三 | C35: 0.5 | D35: 0.875 | E35: 0.66666667 | F35: 0.69791667 | G35: =IF(OR($C$35="",$D$35=""),"",($D$35-$C$35-IF(OR($E$35="",$F$35=""),0,$F$35-$E$35))*24) | H35: =IF(AND($C$35<>"",$D$35<>"",$D$35<=$C$35),"下班需晚於上班",IF(AND($E$35<>"",$F$35<>"",$F$35<=$E$35),"飯鐘結束需晚於開始",IF(AND($E$35<>"",$F$35<>"",OR($E$35<$C$35,$F$35>$D$35)),"飯鐘超出更時",IF(AND($C$35<>"",OR($C$35<'設定 Settings'!$B$12,$D$35>'設定 Settings'!$B$13)),"超出營業時間",""))))
A36: ='設定 Settings'!$A$9 | B36: 星期四 | C36: 0.5 | D36: 0.875 | E36: 0.66666667 | F36: 0.69791667 | G36: =IF(OR($C$36="",$D$36=""),"",($D$36-$C$36-IF(OR($E$36="",$F$36=""),0,$F$36-$E$36))*24) | H36: =IF(AND($C$36<>"",$D$36<>"",$D$36<=$C$36),"下班需晚於上班",IF(AND($E$36<>"",$F$36<>"",$F$36<=$E$36),"飯鐘結束需晚於開始",IF(AND($E$36<>"",$F$36<>"",OR($E$36<$C$36,$F$36>$D$36)),"飯鐘超出更時",IF(AND($C$36<>"",OR($C$36<'設定 Settings'!$B$12,$D$36>'設定 Settings'!$B$13)),"超出營業時間",""))))
A37: ='設定 Settings'!$A$9 | B37: 星期五 | C37: 0.5 | D37: 0.875 | E37: 0.66666667 | F37: 0.69791667 | G37: =IF(OR($C$37="",$D$37=""),"",($D$37-$C$37-IF(OR($E$37="",$F$37=""),0,$F$37-$E$37))*24) | H37: =IF(AND($C$37<>"",$D$37<>"",$D$37<=$C$37),"下班需晚於上班",IF(AND($E$37<>"",$F$37<>"",$F$37<=$E$37),"飯鐘結束需晚於開始",IF(AND($E$37<>"",$F$37<>"",OR($E$37<$C$37,$F$37>$D$37)),"飯鐘超出更時",IF(AND($C$37<>"",OR($C$37<'設定 Settings'!$B$12,$D$37>'設定 Settings'!$B$13)),"超出營業時間",""))))
A38: ='設定 Settings'!$A$9 | B38: 星期六 | C38: 0.5 | D38: 0.875 | E38: 0.66666667 | F38: 0.69791667 | G38: =IF(OR($C$38="",$D$38=""),"",($D$38-$C$38-IF(OR($E$38="",$F$38=""),0,$F$38-$E$38))*24) | H38: =IF(AND($C$38<>"",$D$38<>"",$D$38<=$C$38),"下班需晚於上班",IF(AND($E$38<>"",$F$38<>"",$F$38<=$E$38),"飯鐘結束需晚於開始",IF(AND($E$38<>"",$F$38<>"",OR($E$38<$C$38,$F$38>$D$38)),"飯鐘超出更時",IF(AND($C$38<>"",OR($C$38<'設定 Settings'!$B$12,$D$38>'設定 Settings'!$B$13)),"超出營業時間",""))))
A39: ='設定 Settings'!$A$9 | B39: 星期日 | C39: 0.5 | D39: 0.875 | E39: 0.66666667 | F39: 0.69791667 | G39: =IF(OR($C$39="",$D$39=""),"",($D$39-$C$39-IF(OR($E$39="",$F$39=""),0,$F$39-$E$39))*24) | H39: =IF(AND($C$39<>"",$D$39<>"",$D$39<=$C$39),"下班需晚於上班",IF(AND($E$39<>"",$F$39<>"",$F$39<=$E$39),"飯鐘結束需晚於開始",IF(AND($E$39<>"",$F$39<>"",OR($E$39<$C$39,$F$39>$D$39)),"飯鐘超出更時",IF(AND($C$39<>"",OR($C$39<'設定 Settings'!$B$12,$D$39>'設定 Settings'!$B$13)),"超出營業時間",""))))

Sheet 主排更表
A1: 主排更表 (自動產生 — 請在「員工更表輸入」修改班次)
A2: 顏色：紅=無人覆蓋 橙=人手不足 淺綠=正常 灰=飯鐘。 每格數字 = 當值人數。週末表頭為不同底色。
A3: ① 人手覆蓋 (每格＝當值人數)
A4: 時段 | B4: 星期一 | C4: 星期二 | D4: 星期三 | E4: 星期四 | F4: 星期五 | G4: 星期六 | H4: 星期日
A5: 9:45am-10:15am | B5: =IF(B61="Work",1,0)+IF(B89="Work",1,0)+IF(B117="Work",1,0)+IF(B145="Work",1,0)+IF(B173="Work",1,0) | C5: =IF(C61="Work",1,0)+IF(C89="Work",1,0)+IF(C117="Work",1,0)+IF(C145="Work",1,0)+IF(C173="Work",1,0) | D5: =IF(D61="Work",1,0)+IF(D89="Work",1,0)+IF(D117="Work",1,0)+IF(D145="Work",1,0)+IF(D173="Work",1,0) | E5: =IF(E61="Work",1,0)+IF(E89="Work",1,0)+IF(E117="Work",1,0)+IF(E145="Work",1,0)+IF(E173="Work",1,0) | F5: =IF(F61="Work",1,0)+IF(F89="Work",1,0)+IF(F117="Work",1,0)+IF(F145="Work",1,0)+IF(F173="Work",1,0) | G5: =IF(G61="Work",1,0)+IF(G89="Work",1,0)+IF(G117="Work",1,0)+IF(G145="Work",1,0)+IF(G173="Work",1,0) | H5: =IF(H61="Work",1,0)+IF(H89="Work",1,0)+IF(H117="Work",1,0)+IF(H145="Work",1,0)+IF(H173="Work",1,0) | Z5: =MAX('設定 Settings'!$B$17,IF(AND(OR('設定 Settings'!$A$21="全部",AND('設定 Settings'!$A$21="平日",NOT(OR(B$4="星期六",B$4="星期日"))),AND('設定 Settings'!$A$21="週末",OR(B$4="星期六",B$4="星期日")),'設定 Settings'!$A$21=B$4),Lists!$C$2>='設定 Settings'!$B$21,Lists!$C$2<'設定 Settings'!$C$21),'設定 Settings'!$D$21,0),IF(AND(OR('設定 Settings'!$A$22="全部",AND('設定 Settings'!$A$22="平日",NOT(OR(B$4="星期六",B$4="星期日"))),AND('設定 Settings'!$A$22="週末",OR(B$4="星期六",B$4="星期日")),'設定 Settings'!$A$22=B$4),Lists!$C$2>='設定 Settings'!$B$22,Lists!$C$2<'設定 Settings'!$C$22),'設定 Settings'!$D$22,0),IF(AND(OR('設定 Settings'!$A$23="全部",AND('設定 Settings'!$A$23="平日",NOT(OR(B$4="星期六",B$4="星期日"))),AND('設定 Settings'!$A$23="週末",OR(B$4="星期六",B$4="星期日")),'設定 Settings'!$A$23=B$4),Lists!$C$2>='設定 Settings'!$B$23,Lists!$C$2<'設定 Settings'!$C$23),'設定 Settings'!$D$23,0),IF(AND(OR('設定 Settings'!$A$24="全部",AND('設定 Settings'!$A$24="平日",NOT(OR(B$4="星期六",B$4="星期日"))),AND('設定 Settings'!$A$24="週末",OR(B$4="星期六",B$4="星期日")),'設定 Settings'!$A$24=B$4),Lists!$C$2>='設定 Settings'!$B$24,Lists!$C$2<'設定 Settings'!$C$24),'設定 Settings'!$D$24,0),IF(AND(OR('設定 Settings'!$A$25="全部",AND('設定 Settings'!$A$25="平日",NOT(OR(B$4="星期六",B$4="星期日"))),AND('設定 Settings'!$A$25="週末",OR(B$4="星期六",B$4="星期日")),'設定 Settings'!$A$25=B$4),Lists!$C$2>='設定 Settings'!$B$25,Lists!$C$2<'設定 Settings'!$C$25),'設定 Settings'!$D$25,0),IF(AND(OR('設定 Settings'!$A$26="全部",AND('設定 Settings'!$A$26="平日",NOT(OR(B$4="星期六",B$4="星期日"))),AND('設定 Settings'!$A$26="週末",OR(B$4="星期六",B$4="星期日")),'設定 Settings'!$A$26=B$4),Lists!$C$2>='設定 Settings'!$B$26,Lists!$C$2<'設定 Settings'!$C$26),'設定 Settings'!$D$26,0)) | AA5: =MAX('設定 Settings'!$B$17,IF(AND(OR('設定 Settings'!$A$21="全部",AND('設定 Settings'!$A$21="平日",NOT(OR(C$4="星期六",C$4="星期日"))),AND('設定 Settings'!$A$21="週末",OR(C$4="星期六",C$4="星期日")),'設定 Settings'!$A$21=C$4),Lists!$C$2>='設定 Settings'!$B$21,Lists!$C$2<'設定 Settings'!$C$21),'設定 Settings'!$D$21,0),IF(AND(OR('設定 Settings'!$A$22="全部",AND('設定 Settings'!$A$22="平日",NOT(OR(C$4="星期六",C$4="星期日"))),AND('設定 Settings'!$A$22="週末",OR(C$4="星期六",C$4="星期日")),'設定 Settings'!$A$22=C$4),Lists!$C$2>='設定 Settings'!$B$22,Lists!$C$2<'設定 Settings'!$C$22),'設定 Settings'!$D$22,0),IF(AND(OR('設定 Settings'!$A$23="全部",AND('設定 Settings'!$A$23="平日",NOT(OR(C$4="星期六",C$4="星期日"))),AND('設定 Settings'!$A$23="週末",OR(C$4="星期六",C$4="星期日")),'設定 Settings'!$A$23=C$4),Lists!$C$2>='設定 Settings'!$B$23,Lists!$C$2<'設定 Settings'!$C$23),'設定 Settings'!$D$23,0),IF(AND(OR('設定 Settings'!$A$24="全部",AND('設定 Settings'!$A$24="平日",NOT(OR(C$4="星期六",C$4="星期日"))),AND('設定 Settings'!$A$24="週末",OR(C$4="星期六",C$4="星期日")),'設定 Settings'!$A$24=C$4),Lists!$C$2>='設定 Settings'!$B$24,Lists!$C$2<'設定 Settings'!$C$24),'設定 Settings'!$D$24,0),IF(AND(OR('設定 Settings'!$A$25="全部",AND('設定 Settings'!$A$25="平日",NOT(OR(C$4="星期六",C$4="星期日"))),AND('設定 Settings'!$A$25="週末",OR(C$4="星期六",C$4="星期日")),'設定 Settings'!$A$25=C$4),Lists!$C$2>='設定 Settings'!$B$25,Lists!$C$2<'設定 Settings'!$C$25),'設定 Settings'!$D$25,0),IF(AND(OR('設定 Settings'!$A$26="全部",AND('設定 Settings'!$A$26="平日",NOT(OR(C$4="星期六",C$4="星期日"))),AND('設定 Settings'!$A$26="週末",OR(C$4="星期六",C$4="星期日")),'設定 Settings'!$A$26=C$4),Lists!$C$2>='設定 Settings'!$B$26,Lists!$C$2<'設定 Settings'!$C$26),'設定 Settings'!$D$26,0)) | AB5: =MAX('設定 Settings'!$B$17,IF(AND(OR('設定 Settings'!$A$21="全部",AND('設定 Settings'!$A$21="平日",NOT(OR(D$4="星期六",D$4="星期日"))),AND('設定 Settings'!$A$21="週末",OR(D$4="星期六",D$4="星期日")),'設定 Settings'!$A$21=D$4),Lists!$C$2>='設定 Settings'!$B$21,Lists!$C$2<'設定 Settings'!$C$21),'設定 Settings'!$D$21,0),IF(AND(OR('設定 Settings'!$A$22="全部",AND('設定 Settings'!$A$22="平日",NOT(OR(D$4="星期六",D$4="星期日"))),AND('設定 Settings'!$A$22="週末",OR(D$4="星期六",D$4="星期日")),'設定 Settings'!$A$22=D$4),Lists!$C$2>='設定 Settings'!$B$22,Lists!$C$2<'設定 Settings'!$C$22),'設定 Settings'!$D$22,0),IF(AND(OR('設定 Settings'!$A$23="全部",AND('設定 Settings'!$A$23="平日",NOT(OR(D$4="星期六",D$4="星期日"))),AND('設定 Settings'!$A$23="週末",OR(D$4="星期六",D$4="星期日")),'設定 Settings'!$A$23=D$4),Lists!$C$2>='設定 Settings'!$B$23,Lists!$C$2<'設定 Settings'!$C$23),'設定 Settings'!$D$23,0),IF(AND(OR('設定 Settings'!$A$24="全部",AND('設定 Settings'!$A$24="平日",NOT(OR(D$4="星期六",D$4="星期日"))),AND('設定 Settings'!$A$24="週末",OR(D$4="星期六",D$4="星期日")),'設定 Settings'!$A$24=D$4),Lists!$C$2>='設定 Settings'!$B$24,Lists!$C$2<'設定 Settings'!$C$24),'設定 Settings'!$D$24,0),IF(AND(OR('設定 Settings'!$A$25="全部",AND('設定 Settings'!$A$25="平日",NOT(OR(D$4="星期六",D$4="星期日"))),AND('設定 Settings'!$A$25="週末",OR(D$4="星期六",D$4="星期日")),'設定 Settings'!$A$25=D$4),Lists!$C$2>='設定 Settings'!$B$25,Lists!$C$2<'設定 Settings'!$C$25),'設定 Settings'!$D$25,0),IF(AND(OR('設定 Settings'!$A$26="全部",AND('設定 Settings'!$A$26="平日",NOT(OR(D$4="星期六",D$4="星期日"))),AND('設定 Settings'!$A$26="週末",OR(D$4="星期六",D$4="星期日")),'設定 Settings'!$A$26=D$4),Lists!$C$2>='設定 Settings'!$B$26,Lists!$C$2<'設定 Settings'!$C$26),'設定 Settings'!$D$26,0)) | AC5: =MAX('設定 Settings'!$B$17,IF(AND(OR('設定 Settings'!$A$21="全部",AND('設定 Settings'!$A$21="平日",NOT(OR(E$4="星期六",E$4="星期日"))),AND('設定 Settings'!$A$21="週末",OR(E$4="星期六",E$4="星期日")),'設定 Settings'!$A$21=E$4),Lists!$C$2>='設定 Settings'!$B$21,Lists!$C$2<'設定 Settings'!$C$21),'設定 Settings'!$D$21,0),IF(AND(OR('設定 Settings'!$A$22="全部",AND('設定 Settings'!$A$22="平日",NOT(OR(E$4="星期六",E$4="星期日"))),AND('設定 Settings'!$A$22="週末",OR(E$4="星期六",E$4="星期日")),'設定 Settings'!$A$22=E$4),Lists!$C$2>='設定 Settings'!$B$22,Lists!$C$2<'設定 Settings'!$C$22),'設定 Settings'!$D$22,0),IF(AND(OR('設定 Settings'!$A$23="全部",AND('設定 Settings'!$A$23="平日",NOT(OR(E$4="星期六",E$4="星期日"))),AND('設定 Settings'!$A$23="週末",OR(E$4="星期六",E$4="星期日")),'設定 Settings'!$A$23=E$4),Lists!$C$2>='設定 Settings'!$B$23,Lists!$C$2<'設定 Settings'!$C$23),'設定 Settings'!$D$23,0),IF(AND(OR('設定 Settings'!$A$24="全部",AND('設定 Settings'!$A$24="平日",NOT(OR(E$4="星期六",E$4="星期日"))),AND('設定 Settings'!$A$24="週末",OR(E$4="星期六",E$4="星期日")),'設定 Settings'!$A$24=E$4),Lists!$C$2>='設定 Settings'!$B$24,Lists!$C$2<'設定 Settings'!$C$24),'設定 Settings'!$D$24,0),IF(AND(OR('設定 Settings'!$A$25="全部",AND('設定 Settings'!$A$25="平日",NOT(OR(E$4="星期六",E$4="星期日"))),AND('設定 Settings'!$A$25="週末",OR(E$4="星期六",E$4="星期日")),'設定 Settings'!$A$25=E$4),Lists!$C$2>='設定 Settings'!$B$25,Lists!$C$2<'設定 Settings'!$C$25),'設定 Settings'!$D$25,0),IF(AND(OR('設定 Settings'!$A$26="全部",AND('設定 Settings'!$A$26="平日",NOT(OR(E$4="星期六",E$4="星期日"))),AND('設定 Settings'!$A$26="週末",OR(E$4="星期六",E$4="星期日")),'設定 Settings'!$A$26=E$4),Lists!$C$2>='設定 Settings'!$B$26,Lists!$C$2<'設定 Settings'!$C$26),'設定 Settings'!$D$26,0)) | AD5: =MAX('設定 Settings'!$B$17,IF(AND(OR('設定 Settings'!$A$21="全部",AND('設定 Settings'!$A$21="平日",NOT(OR(F$4="星期六",F$4="星期日"))),AND('設定 Settings'!$A$21="週末",OR(F$4="星期六",F$4="星期日")),'設定 Settings'!$A$21=F$4),Lists!$C$2>='設定 Settings'!$B$21,Lists!$C$2<'設定 Settings'!$C$21),'設定 Settings'!$D$21,0),IF(AND(OR('設定 Settings'!$A$22="全部",AND('設定 Settings'!$A$22="平日",NOT(OR(F$4="星期六",F$4="星期日"))),AND('設定 Settings'!$A$22="週末",OR(F$4="星期六",F$4="星期日")),'設定 Settings'!$A$22=F$4),Lists!$C$2>='設定 Settings'!$B$22,Lists!$C$2<'設定 Settings'!$C$22),'設定 Settings'!$D$22,0),IF(AND(OR('設定 Settings'!$A$23="全部",AND('設定 Settings'!$A$23="平日",NOT(OR(F$4="星期六",F$4="星期日"))),AND('設定 Settings'!$A$23="週末",OR(F$4="星期六",F$4="星期日")),'設定 Settings'!$A$23=F$4),Lists!$C$2>='設定 Settings'!$B$23,Lists!$C$2<'設定 Settings'!$C$23),'設定 Settings'!$D$23,0),IF(AND(OR('設定 Settings'!$A$24="全部",AND('設定 Settings'!$A$24="平日",NOT(OR(F$4="星期六",F$4="星期日"))),AND('設定 Settings'!$A$24="週末",OR(F$4="星期六",F$4="星期日")),'設定 Settings'!$A$24=F$4),Lists!$C$2>='設定 Settings'!$B$24,Lists!$C$2<'設定 Settings'!$C$24),'設定 Settings'!$D$24,0),IF(AND(OR('設定 Settings'!$A$25="全部",AND('設定 Settings'!$A$25="平日",NOT(OR(F$4="星期六",F$4="星期日"))),AND('設定 Settings'!$A$25="週末",OR(F$4="星期六",F$4="星期日")),'設定 Settings'!$A$25=F$4),Lists!$C$2>='設定 Settings'!$B$25,Lists!$C$2<'設定 Settings'!$C$25),'設定 Settings'!$D$25,0),IF(AND(OR('設定 Settings'!$A$26="全部",AND('設定 Settings'!$A$26="平日",NOT(OR(F$4="星期六",F$4="星期日"))),AND('設定 Settings'!$A$26="週末",OR(F$4="星期六",F$4="星期日")),'設定 Settings'!$A$26=F$4),Lists!$C$2>='設定 Settings'!$B$26,Lists!$C$2<'設定 Settings'!$C$26),'設定 Settings'!$D$26,0)) | AE5: =MAX('設定 Settings'!$B$17,IF(AND(OR('設定 Settings'!$A$21="全部",AND('設定 Settings'!$A$21="平日",NOT(OR(G$4="星期六",G$4="星期日"))),AND('設定 Settings'!$A$21="週末",OR(G$4="星期六",G$4="星期日")),'設定 Settings'!$A$21=G$4),Lists!$C$2>='設定 Settings'!$B$21,Lists!$C$2<'設定 Settings'!$C$21),'設定 Settings'!$D$21,0),IF(AND(OR('設定 Settings'!$A$22="全部",AND('設定 Settings'!$A$22="平日",NOT(OR(G$4="星期六",G$4="星期日"))),AND('設定 Settings'!$A$22="週末",OR(G$4="星期六",G$4="星期日")),'設定 Settings'!$A$22=G$4),Lists!$C$2>='設定 Settings'!$B$22,Lists!$C$2<'設定 Settings'!$C$22),'設定 Settings'!$D$22,0),IF(AND(OR('設定 Settings'!$A$23="全部",AND('設定 Settings'!$A$23="平日",NOT(OR(G$4="星期六",G$4="星期日"))),AND('設定 Settings'!$A$23="週末",OR(G$4="星期六",G$4="星期日")),'設定 Settings'!$A$23=G$4),Lists!$C$2>='設定 Settings'!$B$23,Lists!$C$2<'設定 Settings'!$C$23),'設定 Settings'!$D$23,0),IF(AND(OR('設定 Settings'!$A$24="全部",AND('設定 Settings'!$A$24="平日",NOT(OR(G$4="星期六",G$4="星期日"))),AND('設定 Settings'!$A$24="週末",OR(G$4="星期六",G$4="星期日")),'設定 Settings'!$A$24=G$4),Lists!$C$2>='設定 Settings'!$B$24,Lists!$C$2<'設定 Settings'!$C$24),'設定 Settings'!$D$24,0),IF(AND(OR('設定 Settings'!$A$25="全部",AND('設定 Settings'!$A$25="平日",NOT(OR(G$4="星期六",G$4="星期日"))),AND('設定 Settings'!$A$25="週末",OR(G$4="星期六",G$4="星期日")),'設定 Settings'!$A$25=G$4),Lists!$C$2>='設定 Settings'!$B$25,Lists!$C$2<'設定 Settings'!$C$25),'設定 Settings'!$D$25,0),IF(AND(OR('設定 Settings'!$A$26="全部",AND('設定 Settings'!$A$26="平日",NOT(OR(G$4="星期六",G$4="星期日"))),AND('設定 Settings'!$A$26="週末",OR(G$4="星期六",G$4="星期日")),'設定 Settings'!$A$26=G$4),Lists!$C$2>='設定 Settings'!$B$26,Lists!$C$2<'設定 Settings'!$C$26),'設定 Settings'!$D$26,0)) | AF5: =MAX('設定 Settings'!$B$17,IF(AND(OR('設定 Settings'!$A$21="全部",AND('設定 Settings'!$A$21="平日",NOT(OR(H$4="星期六",H$4="星期日"))),AND('設定 Settings'!$A$21="週末",OR(H$4="星期六",H$4="星期日")),'設定 Settings'!$A$21=H$4),Lists!$C$2>='設定 Settings'!$B$21,Lists!$C$2<'設定 Settings'!$C$21),'設定 Settings'!$D$21,0),IF(AND(OR('設定 Settings'!$A$22="全部",AND('設定 Settings'!$A$22="平日",NOT(OR(H$4="星期六",H$4="星期日"))),AND('設定 Settings'!$A$22="週末",OR(H$4="星期六",H$4="星期日")),'設定 Settings'!$A$22=H$4),Lists!$C$2>='設定 Settings'!$B$22,Lists!$C$2<'設定 Settings'!$C$22),'設定 Settings'!$D$22,0),IF(AND(OR('設定 Settings'!$A$23="全部",AND('設定 Settings'!$A$23="平日",NOT(OR(H$4="星期六",H$4="星期日"))),AND('設定 Settings'!$A$23="週末",OR(H$4="星期六",H$4="星期日")),'設定 Settings'!$A$23=H$4),Lists!$C$2>='設定 Settings'!$B$23,Lists!$C$2<'設定 Settings'!$C$23),'設定 Settings'!$D$23,0),IF(AND(OR('設定 Settings'!$A$24="全部",AND('設定 Settings'!$A$24="平日",NOT(OR(H$4="星期六",H$4="星期日"))),AND('設定 Settings'!$A$24="週末",OR(H$4="星期六",H$4="星期日")),'設定 Settings'!$A$24=H$4),Lists!$C$2>='設定 Settings'!$B$24,Lists!$C$2<'設定 Settings'!$C$24),'設定 Settings'!$D$24,0),IF(AND(OR('設定 Settings'!$A$25="全部",AND('設定 Settings'!$A$25="平日",NOT(OR(H$4="星期六",H$4="星期日"))),AND('設定 Settings'!$A$25="週末",OR(H$4="星期六",H$4="星期日")),'設定 Settings'!$A$25=H$4),Lists!$C$2>='設定 Settings'!$B$25,Lists!$C$2<'設定 Settings'!$C$25),'設定 Settings'!$D$25,0),IF(AND(OR('設定 Settings'!$A$26="全部",AND('設定 Settings'!$A$26="平日",NOT(OR(H$4="星期六",H$4="星期日"))),AND('設定 Settings'!$A$26="週末",OR(H$4="星期六",H$4="星期日")),'設定 Settings'!$A$26=H$4),Lists!$C$2>='設定 Settings'!$B$26,Lists!$C$2<'設定 Settings'!$C$26),'設定 Settings'!$D$26,0))
A6: 10:15am-10:45am | B6: =IF(B62="Work",1,0)+IF(B90="Work",1,0)+IF(B118="Work",1,0)+IF(B146="Work",1,0)+IF(B174="Work",1,0) | C6: =IF(C62="Work",1,0)+IF(C90="Work",1,0)+IF(C118="Work",1,0)+IF(C146="Work",1,0)+IF(C174="Work",1,0) | D6: =IF(D62="Work",1,0)+IF(D90="Work",1,0)+IF(D118="Work",1,0)+IF(D146="Work",1,0)+IF(D174="Work",1,0) | E6: =IF(E62="Work",1,0)+IF(E90="Work",1,0)+IF(E118="Work",1,0)+IF(E146="Work",1,0)+IF(E174="Work",1,0) | F6: =IF(F62="Work",1,0)+IF(F90="Work",1,0)+IF(F118="Work",1,0)+IF(F146="Work",1,0)+IF(F174="Work",1,0) | G6: =IF(G62="Work",1,0)+IF(G90="Work",1,0)+IF(G118="Work",1,0)+IF(G146="Work",1,0)+IF(G174="Work",1,0) | H6: =IF(H62="Work",1,0)+IF(H90="Work",1,0)+IF(H118="Work",1,0)+IF(H146="Work",1,0)+IF(H174="Work",1,0) | Z6: =MAX('設定 Settings'!$B$17,IF(AND(OR('設定 Settings'!$A$21="全部",AND('設定 Settings'!$A$21="平日",NOT(OR(B$4="星期六",B$4="星期日"))),AND('設定 Settings'!$A$21="週末",OR(B$4="星期六",B$4="星期日")),'設定 Settings'!$A$21=B$4),Lists!$C$3>='設定 Settings'!$B$21,Lists!$C$3<'設定 Settings'!$C$21),'設定 Settings'!$D$21,0),IF(AND(OR('設定 Settings'!$A$22="全部",AND('設定 Settings'!$A$22="平日",NOT(OR(B$4="星期六",B$4="星期日"))),AND('設定 Settings'!$A$22="週末",OR(B$4="星期六",B$4="星期日")),'設定 Settings'!$A$22=B$4),Lists!$C$3>='設定 Settings'!$B$22,Lists!$C$3<'設定 Settings'!$C$22),'設定 Settings'!$D$22,0),IF(AND(OR('設定 Settings'!$A$23="全部",AND('設定 Settings'!$A$23="平日",NOT(OR(B$4="星期六",B$4="星期日"))),AND('設定 Settings'!$A$23="週末",OR(B$4="星期六",B$4="星期日")),'設定 Settings'!$A$23=B$4),Lists!$C$3>='設定 Settings'!$B$23,Lists!$C$3<'設定 Settings'!$C$23),'設定 Settings'!$D$23,0),IF(AND(OR('設定 Settings'!$A$24="全部",AND('設定 Settings'!$A$24="平日",NOT(OR(B$4="星期六",B$4="星期日"))),AND('設定 Settings'!$A$24="週末",OR(B$4="星期六",B$4="星期日")),'設定 Settings'!$A$24=B$4),Lists!$C$3>='設定 Settings'!$B$24,Lists!$C$3<'設定 Settings'!$C$24),'設定 Settings'!$D$24,0),IF(AND(OR('設定 Settings'!$A$25="全部",AND('設定 Settings'!$A$25="平日",NOT(OR(B$4="星期六",B$4="星期日"))),AND('設定 Settings'!$A$25="週末",OR(B$4="星期六",B$4="星期日")),'設定 Settings'!$A$25=B$4),Lists!$C$3>='設定 Settings'!$B$25,Lists!$C$3<'設定 Settings'!$C$25),'設定 Settings'!$D$25,0),IF(AND(OR('設定 Settings'!$A$26="全部",AND('設定 Settings'!$A$26="平日",NOT(OR(B$4="星期六",B$4="星期日"))),AND('設定 Settings'!$A$26="週末",OR(B$4="星期六",B$4="星期日")),'設定 Settings'!$A$26=B$4),Lists!$C$3>='設定 Settings'!$B$26,Lists!$C$3<'設定 Settings'!$C$26),'設定 Settings'!$D$26,0)) | AA6: =MAX('設定 Settings'!$B$17,IF(AND(OR('設定 Settings'!$A$21="全部",AND('設定 Settings'!$A$21="平日",NOT(OR(C$4="星期六",C$4="星期日"))),AND('設定 Settings'!$A$21="週末",OR(C$4="星期六",C$4="星期日")),'設定 Settings'!$A$21=C$4),Lists!$C$3>='設定 Settings'!$B$21,Lists!$C$3<'設定 Settings'!$C$21),'設定 Settings'!$D$21,0),IF(AND(OR('設定 Settings'!$A$22="全部",AND('設定 Settings'!$A$22="平日",NOT(OR(C$4="星期六",C$4="星期日"))),AND('設定 Settings'!$A$22="週末",OR(C$4="星期六",C$4="星期日")),'設定 Settings'!$A$22=C$4),Lists!$C$3>='設定 Settings'!$B$22,Lists!$C$3<'設定 Settings'!$C$22),'設定 Settings'!$D$22,0),IF(AND(OR('設定 Settings'!$A$23="全部",AND('設定 Settings'!$A$23="平日",NOT(OR(C$4="星期六",C$4="星期日"))),AND('設定 Settings'!$A$23="週末",OR(C$4="星期六",C$4="星期日")),'設定 Settings'!$A$23=C$4),Lists!$C$3>='設定 Settings'!$B$23,Lists!$C$3<'設定 Settings'!$C$23),'設定 Settings'!$D$23,0),IF(AND(OR('設定 Settings'!$A$24="全部",AND('設定 Settings'!$A$24="平日",NOT(OR(C$4="星期六",C$4="星期日"))),AND('設定 Settings'!$A$24="週末",OR(C$4="星期六",C$4="星期日")),'設定 Settings'!$A$24=C$4),Lists!$C$3>='設定 Settings'!$B$24,Lists!$C$3<'設定 Settings'!$C$24),'設定 Settings'!$D$24,0),IF(AND(OR('設定 Settings'!$A$25="全部",AND('設定 Settings'!$A$25="平日",NOT(OR(C$4="星期六",C$4="星期日"))),AND('設定 Settings'!$A$25="週末",OR(C$4="星期六",C$4="星期日")),'設定 Settings'!$A$25=C$4),Lists!$C$3>='設定 Settings'!$B$25,Lists!$C$3<'設定 Settings'!$C$25),'設定 Settings'!$D$25,0),IF(AND(OR('設定 Settings'!$A$26="全部",AND('設定 Settings'!$A$26="平日",NOT(OR(C$4="星期六",C$4="星期日"))),AND('設定 Settings'!$A$26="週末",OR(C$4="星期六",C$4="星期日")),'設定 Settings'!$A$26=C$4),Lists!$C$3>='設定 Settings'!$B$26,Lists!$C$3<'設定 Settings'!$C$26),'設定 Settings'!$D$26,0)) | AB6: =MAX('設定 Settings'!$B$17,IF(AND(OR('設定 Settings'!$A$21="全部",AND('設定 Settings'!$A$21="平日",NOT(OR(D$4="星期六",D$4="星期日"))),AND('設定 Settings'!$A$21="週末",OR(D$4="星期六",D$4="星期日")),'設定 Settings'!$A$21=D$4),Lists!$C$3>='設定 Settings'!$B$21,Lists!$C$3<'設定 Settings'!$C$21),'設定 Settings'!$D$21,0),IF(AND(OR('設定 Settings'!$A$22="全部",AND('設定 Settings'!$A$22="平日",NOT(OR(D$4="星期六",D$4="星期日"))),AND('設定 Settings'!$A$22="週末",OR(D$4="星期六",D$4="星期日")),'設定 Settings'!$A$22=D$4),Lists!$C$3>='設定 Settings'!$B$22,Lists!$C$3<'設定 Settings'!$C$22),'設定 Settings'!$D$22,0),IF(AND(OR('設定 Settings'!$A$23="全部",AND('設定 Settings'!$A$23="平日",NOT(OR(D$4="星期六",D$4="星期日"))),AND('設定 Settings'!$A$23="週末",OR(D$4="星期六",D$4="星期日")),'設定 Settings'!$A$23=D$4),Lists!$C$3>='設定 Settings'!$B$23,Lists!$C$3<'設定 Settings'!$C$23),'設定 Settings'!$D$23,0),IF(AND(OR('設定 Settings'!$A$24="全部",AND('設定 Settings'!$A$24="平日",NOT(OR(D$4="星期六",D$4="星期日"))),AND('設定 Settings'!$A$24="週末",OR(D$4="星期六",D$4="星期日")),'設定 Settings'!$A$24=D$4),Lists!$C$3>='設定 Settings'!$B$24,Lists!$C$3<'設定 Settings'!$C$24),'設定 Settings'!$D$24,0),IF(AND(OR('設定 Settings'!$A$25="全部",AND('設定 Settings'!$A$25="平日",NOT(OR(D$4="星期六",D$4="星期日"))),AND('設定 Settings'!$A$25="週末",OR(D$4="星期六",D$4="星期日")),'設定 Settings'!$A$25=D$4),Lists!$C$3>='設定 Settings'!$B$25,Lists!$C$3<'設定 Settings'!$C$25),'設定 Settings'!$D$25,0),IF(AND(OR('設定 Settings'!$A$26="全部",AND('設定 Settings'!$A$26="平日",NOT(OR(D$4="星期六",D$4="星期日"))),AND('設定 Settings'!$A$26="週末",OR(D$4="星期六",D$4="星期日")),'設定 Settings'!$A$26=D$4),Lists!$C$3>='設定 Settings'!$B$26,Lists!$C$3<'設定 Settings'!$C$26),'設定 Settings'!$D$26,0)) | AC6: =MAX('設定 Settings'!$B$17,IF(AND(OR('設定 Settings'!$A$21="全部",AND('設定 Settings'!$A$21="平日",NOT(OR(E$4="星期六",E$4="星期日"))),AND('設定 Settings'!$A$21="週末",OR(E$4="星期六",E$4="星期日")),'設定 Settings'!$A$21=E$4),Lists!$C$3>='設定 Settings'!$B$21,Lists!$C$3<'設定 Settings'!$C$21),'設定 Settings'!$D$21,0),IF(AND(OR('設定 Settings'!$A$22="全部",AND('設定 Settings'!$A$22="平日",NOT(OR(E$4="星期六",E$4="星期日"))),AND('設定 Settings'!$A$22="週末",OR(E$4="星期六",E$4="星期日")),'設定 Settings'!$A$22=E$4),Lists!$C$3>='設定 Settings'!$B$22,Lists!$C$3<'設定 Settings'!$C$22),'設定 Settings'!$D$22,0),IF(AND(OR('設定 Settings'!$A$23="全部",AND('設定 Settings'!$A$23="平日",NOT(OR(E$4="星期六",E$4="星期日"))),AND('設定 Settings'!$A$23="週末",OR(E$4="星期六",E$4="星期日")),'設定 Settings'!$A$23=E$4),Lists!$C$3>='設定 Settings'!$B$23,Lists!$C$3<'設定 Settings'!$C$23),'設定 Settings'!$D$23,0),IF(AND(OR('設定 Settings'!$A$24="全部",AND('設定 Settings'!$A$24="平日",NOT(OR(E$4="星期六",E$4="星期日"))),AND('設定 Settings'!$A$24="週末",OR(E$4="星期六",E$4="星期日")),'設定 Settings'!$A$24=E$4),Lists!$C$3>='設定 Settings'!$B$24,Lists!$C$3<'設定 Settings'!$C$24),'設定 Settings'!$D$24,0),IF(AND(OR('設定 Settings'!$A$25="全部",AND('設定 Settings'!$A$25="平日",NOT(OR(E$4="星期六",E$4="星期日"))),AND('設定 Settings'!$A$25="週末",OR(E$4="星期六",E$4="星期日")),'設定 Settings'!$A$25=E$4),Lists!$C$3>='設定 Settings'!$B$25,Lists!$C$3<'設定 Settings'!$C$25),'設定 Settings'!$D$25,0),IF(AND(OR('設定 Settings'!$A$26="全部",AND('設定 Settings'!$A$26="平日",NOT(OR(E$4="星期六",E$4="星期日"))),AND('設定 Settings'!$A$26="週末",OR(E$4="星期六",E$4="星期日")),'設定 Settings'!$A$26=E$4),Lists!$C$3>='設定 Settings'!$B$26,Lists!$C$3<'設定 Settings'!$C$26),'設定 Settings'!$D$26,0)) | AD6: =MAX('設定 Settings'!$B$17,IF(AND(OR('設定 Settings'!$A$21="全部",AND('設定 Settings'!$A$21="平日",NOT(OR(F$4="星期六",F$4="星期日"))),AND('設定 Settings'!$A$21="週末",OR(F$4="星期六",F$4="星期日")),'設定 Settings'!$A$21=F$4),Lists!$C$3>='設定 Settings'!$B$21,Lists!$C$3<'設定 Settings'!$C$21),'設定 Settings'!$D$21,0),IF(AND(OR('設定 Settings'!$A$22="全部",AND('設定 Settings'!$A$22="平日",NOT(OR(F$4="星期六",F$4="星期日"))),AND('設定 Settings'!$A$22="週末",OR(F$4="星期六",F$4="星期日")),'設定 Settings'!$A$22=F$4),Lists!$C$3>='設定 Settings'!$B$22,Lists!$C$3<'設定 Settings'!$C$22),'設定 Settings'!$D$22,0),IF(AND(OR('設定 Settings'!$A$23="全部",AND('設定 Settings'!$A$23="平日",NOT(OR(F$4="星期六",F$4="星期日"))),AND('設定 Settings'!$A$23="週末",OR(F$4="星期六",F$4="星期日")),'設定 Settings'!$A$23=F$4),Lists!$C$3>='設定 Settings'!$B$23,Lists!$C$3<'設定 Settings'!$C$23),'設定 Settings'!$D$23,0),IF(AND(OR('設定 Settings'!$A$24="全部",AND('設定 Settings'!$A$24="平日",NOT(OR(F$4="星期六",F$4="星期日"))),AND('設定 Settings'!$A$24="週末",OR(F$4="星期六",F$4="星期日")),'設定 Settings'!$A$24=F$4),Lists!$C$3>='設定 Settings'!$B$24,Lists!$C$3<'設定 Settings'!$C$24),'設定 Settings'!$D$24,0),IF(AND(OR('設定 Settings'!$A$25="全部",AND('設定 Settings'!$A$25="平日",NOT(OR(F$4="星期六",F$4="星期日"))),AND('設定 Settings'!$A$25="週末",OR(F$4="星期六",F$4="星期日")),'設定 Settings'!$A$25=F$4),Lists!$C$3>='設定 Settings'!$B$25,Lists!$C$3<'設定 Settings'!$C$25),'設定 Settings'!$D$25,0),IF(AND(OR('設定 Settings'!$A$26="全部",AND('設定 Settings'!$A$26="平日",NOT(OR(F$4="星期六",F$4="星期日"))),AND('設定 Settings'!$A$26="週末",OR(F$4="星期六",F$4="星期日")),'設定 Settings'!$A$26=F$4),Lists!$C$3>='設定 Settings'!$B$26,Lists!$C$3<'設定 Settings'!$C$26),'設定 Settings'!$D$26,0)) | AE6: =MAX('設定 Settings'!$B$17,IF(AND(OR('設定 Settings'!$A$21="全部",AND('設定 Settings'!$A$21="平日",NOT(OR(G$4="星期六",G$4="星期日"))),AND('設定 Settings'!$A$21="週末",OR(G$4="星期六",G$4="星期日")),'設定 Settings'!$A$21=G$4),Lists!$C$3>='設定 Settings'!$B$21,Lists!$C$3<'設定 Settings'!$C$21),'設定 Settings'!$D$21,0),IF(AND(OR('設定 Settings'!$A$22="全部",AND('設定 Settings'!$A$22="平日",NOT(OR(G$4="星期六",G$4="星期日"))),AND('設定 Settings'!$A$22="週末",OR(G$4="星期六",G$4="星期日")),'設定 Settings'!$A$22=G$4),Lists!$C$3>='設定 Settings'!$B$22,Lists!$C$3<'設定 Settings'!$C$22),'設定 Settings'!$D$22,0),IF(AND(OR('設定 Settings'!$A$23="全部",AND('設定 Settings'!$A$23="平日",NOT(OR(G$4="星期六",G$4="星期日"))),AND('設定 Settings'!$A$23="週末",OR(G$4="星期六",G$4="星期日")),'設定 Settings'!$A$23=G$4),Lists!$C$3>='設定 Settings'!$B$23,Lists!$C$3<'設定 Settings'!$C$23),'設定 Settings'!$D$23,0),IF(AND(OR('設定 Settings'!$A$24="全部",AND('設定 Settings'!$A$24="平日",NOT(OR(G$4="星期六",G$4="星期日"))),AND('設定 Settings'!$A$24="週末",OR(G$4="星期六",G$4="星期日")),'設定 Settings'!$A$24=G$4),Lists!$C$3>='設定 Settings'!$B$24,Lists!$C$3<'設定 Settings'!$C$24),'設定 Settings'!$D$24,0),IF(AND(OR('設定 Settings'!$A$25="全部",AND('設定 Settings'!$A$25="平日",NOT(OR(G$4="星期六",G$4="星期日"))),AND('設定 Settings'!$A$25="週末",OR(G$4="星期六",G$4="星期日")),'設定 Settings'!$A$25=G$4),Lists!$C$3>='設定 Settings'!$B$25,Lists!$C$3<'設定 Settings'!$C$25),'設定 Settings'!$D$25,0),IF(AND(OR('設定 Settings'!$A$26="全部",AND('設定 Settings'!$A$26="平日",NOT(OR(G$4="星期六",G$4="星期日"))),AND('設定 Settings'!$A$26="週末",OR(G$4="星期六",G$4="星期日")),'設定 Settings'!$A$26=G$4),Lists!$C$3>='設定 Settings'!$B$26,Lists!$C$3<'設定 Settings'!$C$26),'設定 Settings'!$D$26,0)) | AF6: =MAX('設定 Settings'!$B$17,IF(AND(OR('設定 Settings'!$A$21="全部",AND('設定 Settings'!$A$21="平日",NOT(OR(H$4="星期六",H$4="星期日"))),AND('設定 Settings'!$A$21="週末",OR(H$4="星期六",H$4="星期日")),'設定 Settings'!$A$21=H$4),Lists!$C$3>='設定 Settings'!$B$21,Lists!$C$3<'設定 Settings'!$C$21),'設定 Settings'!$D$21,0),IF(AND(OR('設定 Settings'!$A$22="全部",AND('設定 Settings'!$A$22="平日",NOT(OR(H$4="星期六",H$4="星期日"))),AND('設定 Settings'!$A$22="週末",OR(H$4="星期六",H$4="星期日")),'設定 Settings'!$A$22=H$4),Lists!$C$3>='設定 Settings'!$B$22,Lists!$C$3<'設定 Settings'!$C$22),'設定 Settings'!$D$22,0),IF(AND(OR('設定 Settings'!$A$23="全部",AND('設定 Settings'!$A$23="平日",NOT(OR(H$4="星期六",H$4="星期日"))),AND('設定 Settings'!$A$23="週末",OR(H$4="星期六",H$4="星期日")),'設定 Settings'!$A$23=H$4),Lists!$C$3>='設定 Settings'!$B$23,Lists!$C$3<'設定 Settings'!$C$23),'設定 Settings'!$D$23,0),IF(AND(OR('設定 Settings'!$A$24="全部",AND('設定 Settings'!$A$24="平日",NOT(OR(H$4="星期六",H$4="星期日"))),AND('設定 Settings'!$A$24="週末",OR(H$4="星期六",H$4="星期日")),'設定 Settings'!$A$24=H$4),Lists!$C$3>='設定 Settings'!$B$24,Lists!$C$3<'設定 Settings'!$C$24),'設定 Settings'!$D$24,0),IF(AND(OR('設定 Settings'!$A$25="全部",AND('設定 Settings'!$A$25="平日",NOT(OR(H$4="星期六",H$4="星期日"))),AND('設定 Settings'!$A$25="週末",OR(H$4="星期六",H$4="星期日")),'設定 Settings'!$A$25=H$4),Lists!$C$3>='設定 Settings'!$B$25,Lists!$C$3<'設定 Settings'!$C$25),'設定 Settings'!$D$25,0),IF(AND(OR('設定 Settings'!$A$26="全部",AND('設定 Settings'!$A$26="平日",NOT(OR(H$4="星期六",H$4="星期日"))),AND('設定 Settings'!$A$26="週末",OR(H$4="星期六",H$4="星期日")),'設定 Settings'!$A$26=H$4),Lists!$C$3>='設定 Settings'!$B$26,Lists!$C$3<'設定 Settings'!$C$26),'設定 Settings'!$D$26,0))
A7: 10:45am-11:15am | B7: =IF(B63="Work",1,0)+IF(B91="Work",1,0)+IF(B119="Work",1,0)+IF(B147="Work",1,0)+IF(B175="Work",1,0) | C7: =IF(C63="Work",1,0)+IF(C91="Work",1,0)+IF(C119="Work",1,0)+IF(C147="Work",1,0)+IF(C175="Work",1,0) | D7: =IF(D63="Work",1,0)+IF(D91="Work",1,0)+IF(D119="Work",1,0)+IF(D147="Work",1,0)+IF(D175="Work",1,0) | E7: =IF(E63="Work",1,0)+IF(E91="Work",1,0)+IF(E119="Work",1,0)+IF(E147="Work",1,0)+IF(E175="Work",1,0) | F7: =IF(F63="Work",1,0)+IF(F91="Work",1,0)+IF(F119="Work",1,0)+IF(F147="Work",1,0)+IF(F175="Work",1,0) | G7: =IF(G63="Work",1,0)+IF(G91="Work",1,0)+IF(G119="Work",1,0)+IF(G147="Work",1,0)+IF(G175="Work",1,0) | H7: =IF(H63="Work",1,0)+IF(H91="Work",1,0)+IF(H119="Work",1,0)+IF(H147="Work",1,0)+IF(H175="Work",1,0) | Z7: =MAX('設定 Settings'!$B$17,IF(AND(OR('設定 Settings'!$A$21="全部",AND('設定 Settings'!$A$21="平日",NOT(OR(B$4="星期六",B$4="星期日"))),AND('設定 Settings'!$A$21="週末",OR(B$4="星期六",B$4="星期日")),'設定 Settings'!$A$21=B$4),Lists!$C$4>='設定 Settings'!$B$21,Lists!$C$4<'設定 Settings'!$C$21),'設定 Settings'!$D$21,0),IF(AND(OR('設定 Settings'!$A$22="全部",AND('設定 Settings'!$A$22="平日",NOT(OR(B$4="星期六",B$4="星期日"))),AND('設定 Settings'!$A$22="週末",OR(B$4="星期六",B$4="星期日")),'設定 Settings'!$A$22=B$4),Lists!$C$4>='設定 Settings'!$B$22,Lists!$C$4<'設定 Settings'!$C$22),'設定 Settings'!$D$22,0),IF(AND(OR('設定 Settings'!$A$23="全部",AND('設定 Settings'!$A$23="平日",NOT(OR(B$4="星期六",B$4="星期日"))),AND('設定 Settings'!$A$23="週末",OR(B$4="星期六",B$4="星期日")),'設定 Settings'!$A$23=B$4),Lists!$C$4>='設定 Settings'!$B$23,Lists!$C$4<'設定 Settings'!$C$23),'設定 Settings'!$D$23,0),IF(AND(OR('設定 Settings'!$A$24="全部",AND('設定 Settings'!$A$24="平日",NOT(OR(B$4="星期六",B$4="星期日"))),AND('設定 Settings'!$A$24="週末",OR(B$4="星期六",B$4="星期日")),'設定 Settings'!$A$24=B$4),Lists!$C$4>='設定 Settings'!$B$24,Lists!$C$4<'設定 Settings'!$C$24),'設定 Settings'!$D$24,0),IF(AND(OR('設定 Settings'!$A$25="全部",AND('設定 Settings'!$A$25="平日",NOT(OR(B$4="星期六",B$4="星期日"))),AND('設定 Settings'!$A$25="週末",OR(B$4="星期六",B$4="星期日")),'設定 Settings'!$A$25=B$4),Lists!$C$4>='設定 Settings'!$B$25,Lists!$C$4<'設定 Settings'!$C$25),'設定 Settings'!$D$25,0),IF(AND(OR('設定 Settings'!$A$26="全部",AND('設定 Settings'!$A$26="平日",NOT(OR(B$4="星期六",B$4="星期日"))),AND('設定 Settings'!$A$26="週末",OR(B$4="星期六",B$4="星期日")),'設定 Settings'!$A$26=B$4),Lists!$C$4>='設定 Settings'!$B$26,Lists!$C$4<'設定 Settings'!$C$26),'設定 Settings'!$D$26,0)) | AA7: =MAX('設定 Settings'!$B$17,IF(AND(OR('設定 Settings'!$A$21="全部",AND('設定 Settings'!$A$21="平日",NOT(OR(C$4="星期六",C$4="星期日"))),AND('設定 Settings'!$A$21="週末",OR(C$4="星期六",C$4="星期日")),'設定 Settings'!$A$21=C$4),Lists!$C$4>='設定 Settings'!$B$21,Lists!$C$4<'設定 Settings'!$C$21),'設定 Settings'!$D$21,0),IF(AND(OR('設定 Settings'!$A$22="全部",AND('設定 Settings'!$A$22="平日",NOT(OR(C$4="星期六",C$4="星期日"))),AND('設定 Settings'!$A$22="週末",OR(C$4="星期六",C$4="星期日")),'設定 Settings'!$A$22=C$4),Lists!$C$4>='設定 Settings'!$B$22,Lists!$C$4<'設定 Settings'!$C$22),'設定 Settings'!$D$22,0),IF(AND(OR('設定 Settings'!$A$23="全部",AND('設定 Settings'!$A$23="平日",NOT(OR(C$4="星期六",C$4="星期日"))),AND('設定 Settings'!$A$23="週末",OR(C$4="星期六",C$4="星期日")),'設定 Settings'!$A$23=C$4),Lists!$C$4>='設定 Settings'!$B$23,Lists!$C$4<'設定 Settings'!$C$23),'設定 Settings'!$D$23,0),IF(AND(OR('設定 Settings'!$A$24="全部",AND('設定 Settings'!$A$24="平日",NOT(OR(C$4="星期六",C$4="星期日"))),AND('設定 Settings'!$A$24="週末",OR(C$4="星期六",C$4="星期日")),'設定 Settings'!$A$24=C$4),Lists!$C$4>='設定 Settings'!$B$24,Lists!$C$4<'設定 Settings'!$C$24),'設定 Settings'!$D$24,0),IF(AND(OR('設定 Settings'!$A$25="全部",AND('設定 Settings'!$A$25="平日",NOT(OR(C$4="星期六",C$4="星期日"))),AND('設定 Settings'!$A$25="週末",OR(C$4="星期六",C$4="星期日")),'設定 Settings'!$A$25=C$4),Lists!$C$4>='設定 Settings'!$B$25,Lists!$C$4<'設定 Settings'!$C$25),'設定 Settings'!$D$25,0),IF(AND(OR('設定 Settings'!$A$26="全部",AND('設定 Settings'!$A$26="平日",NOT(OR(C$4="星期六",C$4="星期日"))),AND('設定 Settings'!$A$26="週末",OR(C$4="星期六",C$4="星期日")),'設定 Settings'!$A$26=C$4),Lists!$C$4>='設定 Settings'!$B$26,Lists!$C$4<'設定 Settings'!$C$26),'設定 Settings'!$D$26,0)) | AB7: =MAX('設定 Settings'!$B$17,IF(AND(OR('設定 Settings'!$A$21="全部",AND('設定 Settings'!$A$21="平日",NOT(OR(D$4="星期六",D$4="星期日"))),AND('設定 Settings'!$A$21="週末",OR(D$4="星期六",D$4="星期日")),'設定 Settings'!$A$21=D$4),Lists!$C$4>='設定 Settings'!$B$21,Lists!$C$4<'設定 Settings'!$C$21),'設定 Settings'!$D$21,0),IF(AND(OR('設定 Settings'!$A$22="全部",AND('設定 Settings'!$A$22="平日",NOT(OR(D$4="星期六",D$4="星期日"))),AND('設定 Settings'!$A$22="週末",OR(D$4="星期六",D$4="星期日")),'設定 Settings'!$A$22=D$4),Lists!$C$4>='設定 Settings'!$B$22,Lists!$C$4<'設定 Settings'!$C$22),'設定 Settings'!$D$22,0),IF(AND(OR('設定 Settings'!$A$23="全部",AND('設定 Settings'!$A$23="平日",NOT(OR(D$4="星期六",D$4="星期日"))),AND('設定 Settings'!$A$23="週末",OR(D$4="星期六",D$4="星期日")),'設定 Settings'!$A$23=D$4),Lists!$C$4>='設定 Settings'!$B$23,Lists!$C$4<'設定 Settings'!$C$23),'設定 Settings'!$D$23,0),IF(AND(OR('設定 Settings'!$A$24="全部",AND('設定 Settings'!$A$24="平日",NOT(OR(D$4="星期六",D$4="星期日"))),AND('設定 Settings'!$A$24="週末",OR(D$4="星期六",D$4="星期日")),'設定 Settings'!$A$24=D$4),Lists!$C$4>='設定 Settings'!$B$24,Lists!$C$4<'設定 Settings'!$C$24),'設定 Settings'!$D$24,0),IF(AND(OR('設定 Settings'!$A$25="全部",AND('設定 Settings'!$A$25="平日",NOT(OR(D$4="星期六",D$4="星期日"))),AND('設定 Settings'!$A$25="週末",OR(D$4="星期六",D$4="星期日")),'設定 Settings'!$A$25=D$4),Lists!$C$4>='設定 Settings'!$B$25,Lists!$C$4<'設定 Settings'!$C$25),'設定 Settings'!$D$25,0),IF(AND(OR('設定 Settings'!$A$26="全部",AND('設定 Settings'!$A$26="平日",NOT(OR(D$4="星期六",D$4="星期日"))),AND('設定 Settings'!$A$26="週末",OR(D$4="星期六",D$4="星期日")),'設定 Settings'!$A$26=D$4),Lists!$C$4>='設定 Settings'!$B$26,Lists!$C$4<'設定 Settings'!$C$26),'設定 Settings'!$D$26,0)) | AC7: =MAX('設定 Settings'!$B$17,IF(AND(OR('設定 Settings'!$A$21="全部",AND('設定 Settings'!$A$21="平日",NOT(OR(E$4="星期六",E$4="星期日"))),AND('設定 Settings'!$A$21="週末",OR(E$4="星期六",E$4="星期日")),'設定 Settings'!$A$21=E$4),Lists!$C$4>='設定 Settings'!$B$21,Lists!$C$4<'設定 Settings'!$C$21),'設定 Settings'!$D$21,0),IF(AND(OR('設定 Settings'!$A$22="全部",AND('設定 Settings'!$A$22="平日",NOT(OR(E$4="星期六",E$4="星期日"))),AND('設定 Settings'!$A$22="週末",OR(E$4="星期六",E$4="星期日")),'設定 Settings'!$A$22=E$4),Lists!$C$4>='設定 Settings'!$B$22,Lists!$C$4<'設定 Settings'!$C$22),'設定 Settings'!$D$22,0),IF(AND(OR('設定 Settings'!$A$23="全部",AND('設定 Settings'!$A$23="平日",NOT(OR(E$4="星期六",E$4="星期日"))),AND('設定 Settings'!$A$23="週末",OR(E$4="星期六",E$4="星期日")),'設定 Settings'!$A$23=E$4),Lists!$C$4>='設定 Settings'!$B$23,Lists!$C$4<'設定 Settings'!$C$23),'設定 Settings'!$D$23,0),IF(AND(OR('設定 Settings'!$A$24="全部",AND('設定 Settings'!$A$24="平日",NOT(OR(E$4="星期六",E$4="星期日"))),AND('設定 Settings'!$A$24="週末",OR(E$4="星期六",E$4="星期日")),'設定 Settings'!$A$24=E$4),Lists!$C$4>='設定 Settings'!$B$24,Lists!$C$4<'設定 Settings'!$C$24),'設定 Settings'!$D$24,0),IF(AND(OR('設定 Settings'!$A$25="全部",AND('設定 Settings'!$A$25="平日",NOT(OR(E$4="星期六",E$4="星期日"))),AND('設定 Settings'!$A$25="週末",OR(E$4="星期六",E$4="星期日")),'設定 Settings'!$A$25=E$4),Lists!$C$4>='設定 Settings'!$B$25,Lists!$C$4<'設定 Settings'!$C$25),'設定 Settings'!$D$25,0),IF(AND(OR('設定 Settings'!$A$26="全部",AND('設定 Settings'!$A$26="平日",NOT(OR(E$4="星期六",E$4="星期日"))),AND('設定 Settings'!$A$26="週末",OR(E$4="星期六",E$4="星期日")),'設定 Settings'!$A$26=E$4),Lists!$C$4>='設定 Settings'!$B$26,Lists!$C$4<'設定 Settings'!$C$26),'設定 Settings'!$D$26,0)) | AD7: =MAX('設定 Settings'!$B$17,IF(AND(OR('設定 Settings'!$A$21="全部",AND('設定 Settings'!$A$21="平日",NOT(OR(F$4="星期六",F$4="星期日"))),AND('設定 Settings'!$A$21="週末",OR(F$4="星期六",F$4="星期日")),'設定 Settings'!$A$21=F$4),Lists!$C$4>='設定 Settings'!$B$21,Lists!$C$4<'設定 Settings'!$C$21),'設定 Settings'!$D$21,0),IF(AND(OR('設定 Settings'!$A$22="全部",AND('設定 Settings'!$A$22="平日",NOT(OR(F$4="星期六",F$4="星期日"))),AND('設定 Settings'!$A$22="週末",OR(F$4="星期六",F$4="星期日")),'設定 Settings'!$A$22=F$4),Lists!$C$4>='設定 Settings'!$B$22,Lists!$C$4<'設定 Settings'!$C$22),'設定 Settings'!$D$22,0),IF(AND(OR('設定 Settings'!$A$23="全部",AND('設定 Settings'!$A$23="平日",NOT(OR(F$4="星期六",F$4="星期日"))),AND('設定 Settings'!$A$23="週末",OR(F$4="星期六",F$4="星期日")),'設定 Settings'!$A$23=F$4),Lists!$C$4>='設定 Settings'!$B$23,Lists!$C$4<'設定 Settings'!$C$23),'設定 Settings'!$D$23,0),IF(AND(OR('設定 Settings'!$A$24="全部",AND('設定 Settings'!$A$24="平日",NOT(OR(F$4="星期六",F$4="星期日"))),AND('設定 Settings'!$A$24="週末",OR(F$4="星期六",F$4="星期日")),'設定 Settings'!$A$24=F$4),Lists!$C$4>='設定 Settings'!$B$24,Lists!$C$4<'設定 Settings'!$C$24),'設定 Settings'!$D$24,0),IF(AND(OR('設定 Settings'!$A$25="全部",AND('設定 Settings'!$A$25="平日",NOT(OR(F$4="星期六",F$4="星期日"))),AND('設定 Settings'!$A$25="週末",OR(F$4="星期六",F$4="星期日")),'設定 Settings'!$A$25=F$4),Lists!$C$4>='設定 Settings'!$B$25,Lists!$C$4<'設定 Settings'!$C$25),'設定 Settings'!$D$25,0),IF(AND(OR('設定 Settings'!$A$26="全部",AND('設定 Settings'!$A$26="平日",NOT(OR(F$4="星期六",F$4="星期日"))),AND('設定 Settings'!$A$26="週末",OR(F$4="星期六",F$4="星期日")),'設定 Settings'!$A$26=F$4),Lists!$C$4>='設定 Settings'!$B$26,Lists!$C$4<'設定 Settings'!$C$26),'設定 Settings'!$D$26,0)) | AE7: =MAX('設定 Settings'!$B$17,IF(AND(OR('設定 Settings'!$A$21="全部",AND('設定 Settings'!$A$21="平日",NOT(OR(G$4="星期六",G$4="星期日"))),AND('設定 Settings'!$A$21="週末",OR(G$4="星期六",G$4="星期日")),'設定 Settings'!$A$21=G$4),Lists!$C$4>='設定 Settings'!$B$21,Lists!$C$4<'設定 Settings'!$C$21),'設定 Settings'!$D$21,0),IF(AND(OR('設定 Settings'!$A$22="全部",AND('設定 Settings'!$A$22="平日",NOT(OR(G$4="星期六",G$4="星期日"))),AND('設定 Settings'!$A$22="週末",OR(G$4="星期六",G$4="星期日")),'設定 Settings'!$A$22=G$4),Lists!$C$4>='設定 Settings'!$B$22,Lists!$C$4<'設定 Settings'!$C$22),'設定 Settings'!$D$22,0),IF(AND(OR('設定 Settings'!$A$23="全部",AND('設定 Settings'!$A$23="平日",NOT(OR(G$4="星期六",G$4="星期日"))),AND('設定 Settings'!$A$23="週末",OR(G$4="星期六",G$4="星期日")),'設定 Settings'!$A$23=G$4),Lists!$C$4>='設定 Settings'!$B$23,Lists!$C$4<'設定 Settings'!$C$23),'設定 Settings'!$D$23,0),IF(AND(OR('設定 Settings'!$A$24="全部",AND('設定 Settings'!$A$24="平日",NOT(OR(G$4="星期六",G$4="星期日"))),AND('設定 Settings'!$A$24="週末",OR(G$4="星期六",G$4="星期日")),'設定 Settings'!$A$24=G$4),Lists!$C$4>='設定 Settings'!$B$24,Lists!$C$4<'設定 Settings'!$C$24),'設定 Settings'!$D$24,0),IF(AND(OR('設定 Settings'!$A$25="全部",AND('設定 Settings'!$A$25="平日",NOT(OR(G$4="星期六",G$4="星期日"))),AND('設定 Settings'!$A$25="週末",OR(G$4="星期六",G$4="星期日")),'設定 Settings'!$A$25=G$4),Lists!$C$4>='設定 Settings'!$B$25,Lists!$C$4<'設定 Settings'!$C$25),'設定 Settings'!$D$25,0),IF(AND(OR('設定 Settings'!$A$26="全部",AND('設定 Settings'!$A$26="平日",NOT(OR(G$4="星期六",G$4="星期日"))),AND('設定 Settings'!$A$26="週末",OR(G$4="星期六",G$4="星期日")),'設定 Settings'!$A$26=G$4),Lists!$C$4>='設定 Settings'!$B$26,Lists!$C$4<'設定 Settings'!$C$26),'設定 Settings'!$D$26,0)) | AF7: =MAX('設定 Settings'!$B$17,IF(AND(OR('設定 Settings'!$A$21="全部",AND('設定 Settings'!$A$21="平日",NOT(OR(H$4="星期六",H$4="星期日"))),AND('設定 Settings'!$A$21="週末",OR(H$4="星期六",H$4="星期日")),'設定 Settings'!$A$21=H$4),Lists!$C$4>='設定 Settings'!$B$21,Lists!$C$4<'設定 Settings'!$C$21),'設定 Settings'!$D$21,0),IF(AND(OR('設定 Settings'!$A$22="全部",AND('設定 Settings'!$A$22="平日",NOT(OR(H$4="星期六",H$4="星期日"))),AND('設定 Settings'!$A$22="週末",OR(H$4="星期六",H$4="星期日")),'設定 Settings'!$A$22=H$4),Lists!$C$4>='設定 Settings'!$B$22,Lists!$C$4<'設定 Settings'!$C$22),'設定 Settings'!$D$22,0),IF(AND(OR('設定 Settings'!$A$23="全部",AND('設定 Settings'!$A$23="平日",NOT(OR(H$4="星期六",H$4="星期日"))),AND('設定 Settings'!$A$23="週末",OR(H$4="星期六",H$4="星期日")),'設定 Settings'!$A$23=H$4),Lists!$C$4>='設定 Settings'!$B$23,Lists!$C$4<'設定 Settings'!$C$23),'設定 Settings'!$D$23,0),IF(AND(OR('設定 Settings'!$A$24="全部",AND('設定 Settings'!$A$24="平日",NOT(OR(H$4="星期六",H$4="星期日"))),AND('設定 Settings'!$A$24="週末",OR(H$4="星期六",H$4="星期日")),'設定 Settings'!$A$24=H$4),Lists!$C$4>='設定 Settings'!$B$24,Lists!$C$4<'設定 Settings'!$C$24),'設定 Settings'!$D$24,0),IF(AND(OR('設定 Settings'!$A$25="全部",AND('設定 Settings'!$A$25="平日",NOT(OR(H$4="星期六",H$4="星期日"))),AND('設定 Settings'!$A$25="週末",OR(H$4="星期六",H$4="星期日")),'設定 Settings'!$A$25=H$4),Lists!$C$4>='設定 Settings'!$B$25,Lists!$C$4<'設定 Settings'!$C$25),'設定 Settings'!$D$25,0),IF(AND(OR('設定 Settings'!$A$26="全部",AND('設定 Settings'!$A$26="平日",NOT(OR(H$4="星期六",H$4="星期日"))),AND('設定 Settings'!$A$26="週末",OR(H$4="星期六",H$4="星期日")),'設定 Settings'!$A$26=H$4),Lists!$C$4>='設定 Settings'!$B$26,Lists!$C$4<'設定 Settings'!$C$26),'設定 Settings'!$D$26,0))
